Workbook
Name __123Graph_LBL_C投資推移: #REF!
Name __123Graph_A投資推移: #REF!
Name 철구사업본부: #REF!
Name CTS: #REF!
Name cc: #REF!
Name graph: #REF!
Name __123Graph_LBL_A投資推移: #REF!
Name __123Graph_C投資推移: #REF!
Name Print_Area_MI: #REF!
Name 饿: #REF!
Name 前期: #REF!
Name 전: #REF!
Name Print_Area_MI: #REF!
Name Print_Area_MI: #REF!
Name cc: #REF!
Name pp: #REF!
Name qq: #REF!
Name __123Graph_A投資推移: #REF!
Name 哦: #REF!
Name __123Graph_C投資推移: #REF!
Name dd: #REF!
Name __123Graph_LBL_D投資推移: #REF!
Name graph: #REF!
Name 资金预测3: #REF!
Name bb: #REF!
Name __123Graph_LBL_A投資推移: #REF!
Name __123Graph_LBL_C投資推移: #REF!
Name dd: #REF!
Name Hello: #REF!
Name wrn.pp.: #REF!
Name 哦: #REF!
Name bb: #REF!
Name wrn.pp.: #REF!
Name _Fill: #REF!
Name _Key1: #REF!
Name gg: #REF!
Name 资金预测3: #REF!
Name CTS: #REF!
Name __123Graph_LBL_D投資推移: #REF!
Name _Fill: #REF!
Name qwe: #REF!
Name gg: #REF!
Name ww: #REF!
Name 주택사업본부: #REF!
Name CTS: #REF!
Name __123Graph_A投資推移: #REF!
Name ww: #REF!
Name qq: #REF!
Name 前期: #REF!
Name qwe: #REF!
Name _Key1: #REF!
Name pp: #REF!

Sheet 開發計畫表(封面)
A1: Caddy California 露營車 多量認證車 開發計畫表
A4: 主擔當 | B4: 產品部 郭文宗
A6: 專案成員 | B6: 產品部 江冠毅、林保伶、黃德生
A8: 對象車 | B8: 2023款 Caddy California 露營車
A10: 產品類型 | B10: 掀頂帳設計
A12: 營業需求 | B12: 150 台/年
A14: 開發案代號 | B14: 2308CDR01 (若 GM 通過，可使用此專案代號)
A16: 專案目標 | B16: 2024/Q3 量產移行完成
A18: 項次 | B18: 項目 | G18: 需要與否 | H18: 主擔當 | I18: 預計 完成日
A19: 1 | B19: 技術可行性評估報告 | G19: ○ | H19: 小郭 | I19: 45145
A20: 2 | B20: 工程規格(初步設計) | G20: ○ | H20: 小郭 | I20: 45145
A21: 3 | B21: 產品規格 | G21: ○ | H21: 小郭 | I21: 45145
A22: 4 | B22: 舊款BOM表參照 | G22: × | H22: × | I22: ×
A23: 5 | B23: 配置圖面(含尺寸) | G23: × | H23: × | I23: ×
A24: 6 | B24: 工程圖面(含尺寸) | G24: ○ | H24: 小郭 | I24: 45145
A25: 7 | B25: 大日程計畫表(A表) 含(跨部橫展計畫、產品開發計劃、預算、MSRP售價推估) | G25: ○ | H25: 小郭 | I25: 45145
A26: 8 | B26: 新材料開發計畫表(B表) | G26: ○ | H26: 小郭 | I26: 45145
A27: 9 | B27: 模治具開發計畫(C表) | G27: ○ | H27: 小郭 | I27: 45145
A28: 10 | B28: 品質技術保證計畫(D表) | G28: ○ | H28: 思凱 | I28: 45145
A29: 備註：
A37: 業務行銷部
A38: 產品研發部
A39: 品質保證部
A40: 生產製造部
A41: 管理行政部
A42: 核 准 | D42: 審 核 | G42: 作 成
G43: 郭文宗
G46: 112/06/15 V01.TB-T53-0

Sheet A表-大日程計畫表(橫展跨部版)
C1: 台灣福祉科技有限公司 CENTRAL TRANSACTION SERVICES CO., LTD. 【小型特種車(露營車)】大日程計畫表 （A表） | AN1: 專案 核決 | AS1: 專案 審查 | AX1: 專案 經理 | BC1: 專案 成員
B2: 目標計畫 | C2: 小型特種車(露營車) 高價市場 Caddy California 產品上市 | M2: 方針 | O2: 露營車高價市場測試 | T2: 產品研發Policy | Y2: 低於 200萬售價 的 價格帶 | AN2: 地點 | AP2: 樹八廠 | AV2: 版本 | AX2: 2022.06.13
B3: 企業循環- 階段-任務 | C3: 是否 執行 | D3: 是否 完成 | E3: 產出物(Artifacts) | J3: 工時估算 | M3: 責任部門 | N3: 責任者 | O3: Gate 1: 資本支出 簽核通過 及 車到啟動本案
J4: 天數 | K4: 人數 | L4: 人天數 | O4: W1 | P4: W2 | Q4: W3 | R4: W4 | S4: Kick-off | T4: W1 | U4: W2 | V4: W3 | W4: W4 | X4: W5 | Y4: W6 | Z4: W7 | AA4: W8 | AB4: W9 | AC4: W10 | AD4: W11 | AE4: W12 | AF4: W13 | AG4: W14 | AH4: W15 | AI4: W16 | AJ4: W17 | AK4: W18 | AL4: W19 | AM4: W20 | AN4: W21 | AO4: W22 | AP4: W23 | AQ4: W24 | AR4: W25 | AS4: W26 | AT4: W27 | AU4: W28 | AV4: W29 | AW4: W30 | AX4: W31 | AY4: W32 | AZ4: W33 | BA4: W34 | BB4: W35 | BC4: W36 | BD4: W37 | BE4: W38 | BF4: W39 | BG4: W40 | BH4: W41 | BI4: W42 | BJ4: W43 | BK4: W44
B5: GATE 0: 評審(報價許可) | C5: ■ | D5: □ | E5: TB-P02 跨部簽核 (含 附件) | M5: 董事長室 | N5: GM | O5: 45138 | P5: 45145 | Q5: 45159 | R5: 45166
B6: GATE 1: 評審(資本支出許可) | C6: ■ | D6: □ | E6: 1. TB-T97 正式成案 (含 TB-T02 及 附件) 2. (通過後)專案財務開帳 | M6: 總經理 | N6: GM | S6: ▲
B7: ②認證車設計 (反向工程) | C7: ■ | D7: □ | E7: 掀頂改高總成 (含 車頂內裝) FRP 開模設計及委製 | J7: 10 | K7: 1 | L7: =J7*K7 -> 10 | M7: 產品研發部 | N7: 產品工程師
C8: ■ | D8: □ | E8: 建立 產品結構 (試製品) P-BOM | J8: 1 | K8: 1 | L8: =J8*K8 -> 1 | M8: 產品研發部 | N8: 產品工程師
B9: ③採購委製零組件 | C9: ■ | D9: □ | E9: 採購 原廠車輛 (2023年款-Caddy California) | J9: 0.25 | K9: 1 | L9: 0.25 | M9: 管理行政部 | N9: 研發採購 | T9: 車到日
C10: ■ | D10: □ | E10: 委製 料件- 掀頂改高總成 (含 車頂內裝) | J10: 0.25 | K10: 1 | L10: 0.25 | M10: 管理行政部 | N10: 研發採購 | U10: ▲車到日 | X10: ▲車到日+1個月
B11: ④打造認證車 | C11: ■ | D11: □ | E11: 產品工程開發計畫，詳：A表-附件-產品工程開發計畫 | J11: 40 | K11: 2 | L11: =J11*K11 -> 80 | M11: 產品研發部 | N11: 產品工程師
C12: ■ | D12: □ | E12: 打造結果品質確認及廠內產品測試 | J12: 2 | K12: 2 | L12: =J12*K12 -> 4 | M12: 產品研發部 | N12: 產品工程師 | AB12: ▲ | AE12: ▲ | AG12: ▲ | AI12: ▲
B13: ⑤發展ISO各階文件 | C13: ■ | D13: □ | E13: 製作 WP-T2X Caddy California 小型特種車(露營車) 製程規範 | J13: 2 | K13: 2 | L13: =J13*K13 -> 4 | M13: 產品研發部 | N13: 產品工程師
C14: ■ | D14: □ | E14: 製作 TB-T05 Caddy California 小型特種車(露營車) 自主檢查表 (60%委外) | J14: 2 | K14: 2 | L14: =J14*K14 -> 4 | M14: 產品研發部 | N14: 產品工程師
C15: ■ | D15: □ | E15: 製作 TB-T0X Caddy California 掀頂改高總成檢查表 | J15: 5 | K15: 1 | L15: =J15*K15 -> 5 | M15: 產品研發部 | N15: 產品工程師
C16: ■ | D16: □ | E16: 製作 TB-T04Caddy California 小型特種車(露營車) 成品檢查表 | J16: 5 | K16: 1 | L16: =J16*K16 -> 5 | M16: 品質保證部 | N16: 品管工程師
C17: ■ | D17: □ | E17: 製作 WC-T11 檢驗作業規範-小型特種車(露營車) | J17: 5 | K17: 1 | L17: =J17*K17 -> 5 | M17: 品質保證部 | N17: 品管工程師
C18: ■ | D18: □ | E18: 更新 ISO 一二階文件 及 對焦 VSCC 輸出文件 | J18: 5 | K18: 1 | L18: =J18*K18 -> 5 | N18: EAG
B19: ⑦原廠確認打造工法及原廠測試 | C19: ■ | D19: □ | E19: 拖車物流 | M19: 產品研發部 | N19: 產品工程師 | AM19: ▲
C20: ■ | D20: □ | E20: 原廠測試及NG反修 | J20: 1 | K20: 2 | L20: =J20*K20 -> 2 | M20: 產品研發部 | N20: 產品工程師 | AO20: ▲
B21: ⑥能力證明並獲得授權書 | C21: ■ | D21: □ | E21: 授權書 | M21: 產品研發部 | N21: 產品法規 | AP21: ▲
B22: ⑨ROUND 1:登錄車身打造廠打造該車型資格(4-8週) | C22: ■ | D22: □ | E22: 申請者資格變更登錄(新車型登錄) 品質一致性管制計畫書審查 工廠查核作業 | J22: 10 | K22: 1 | L22: =J22*K22 -> 10 | M22: 產品研發部 | N22: 產品法規 | AQ22: ▲ | AS22: ▲ | AW22: ▲
B23: Gate 2: 二階段關卡評審 (原型產品) | C23: ■ | D23: □ | E23: 1.通過法規檢測之原型產品 2.產品計畫 (A、B、C、D) 四表 [更新版] 3.財務料帳結算 [更新版] 4.第一次 (跨部會) 產品說明會 [聽取反饋建議] 5.試製品P-BOM表建立 | M23: 總經理 | N23: GM
B24: ⑩ROUND 2: 審查報告及授權 | C24: ■ | D24: □ | E24: 0.原廠符合性宣告表 1.R點測試報告 及 R點宣告書 2.原廠車輛規格表 3.車輛安全檢測基準測試報告 (ARTC) 4.車輛安全檢測基準審查報告 5.原廠車輛 審查報告 及 審查報告授權書 6.原廠供應商 審查報告 及 審查報告授權書 7.福祉供應商 審查報告 及 審查報告授權書 8.安全玻璃安全帶門閂鉸鏈聲明書 9.認證車符合性宣告表 | J24: 5 | K24: 1 | L24: =J24*K24 -> 5 | M24: 產品研發部 | N24: 產品法規
B25: ⑧法規檢驗(測試報告) 020/040 ⑪ROUND 3: 新車型審驗(4-8週) | C25: ■ | D25: □ | E25: 0.新車型審驗 (掛案/補件/結案) 1.廠牌及型式系列聲明書 2.改裝聲明書 3.完成車照片 4.車身及引擎號碼打刻位置與示意圖 5.車輛規格表(法測後更新版) 6.車主手冊 7.車輛使用手冊註明法規符合性內容聲明 | J25: 10 | K25: 1 | L25: =J25*K25 -> 10 | M25: 產品研發部 | N25: 產品法規 | AW25: ▲ | AY25: ▲ | BD25: ▲
B26: ⑫生產準備(量產移行/試量產) | C26: ■ | D26: □ | E26: 1.量產移行計畫 (5M預備) 2.產品計畫 (C、D) 四表 [更新版] 3.商品化產品教育訓練及技術移轉 4.產能規劃及預測 5.建立產品結構 (正式品) P-BOM表 6.QRQC 現場改善行動 7.生管到位展開生產模擬 | M26: 產品研發部 | N26: 產品工程師 | AQ26: ▲商品化 | AW26: ▲試量產 | BD26: ▲正式量產
B27: Gate 3: 三階段關卡評審 (試量產品) | C27: ■ | D27: □ | E27: 1.通過審驗獲得合格證之商品化產品 2.產品計畫 (A、B、C、D) 四表 [更新版] 3.料帳結算 [更新版] 4.第二次 (跨部會) 產品說明會 [聽取反饋建議] 5.量產(正式品)P-BOM建立 | M27: 總經理 | N27: GM
B28: ⑬量產製程及工法改善 | C28: ■ | D28: □ | E28: 正式量產 | M28: 生產製造部 | N28: 組長 | BD28: ▲ | BF28: ▲ | BH28: ▲ | BJ28: ▲
B29: Gate 4: 四階段關卡評審 (量產產品) | C29: ■ | D29: □ | E29: 1.建立安全庫存量 2.售後服務建立 3.降低量產成本 4.確認生產品質 | M29: 總經理 | N29: GM
B30: ⑭上市 | C30: ■ | D30: □ | E30: 上市行銷活動 | M30: 行銷業務部 | BD30: ▲ | BF30: ▲ | BH30: ▲ | BJ30: ▲
J31: 總計人天數 | L31: =SUM(L9:L30) -> 139.5
L32: 112/06/15 V01.TB-T53

Sheet A表-附件-產品開發計畫
G1: 新產品開發計畫 （A表）-附件 (產品工程) | Y1: 專案 經理
A2: 專案項目名稱 | G2: 客戶名稱
A3: 階段 / 任務項目 | B3: 文件名稱 | G3: 責任部門 | AD3: PM 確認
H4: W1 | I4: W2 | J4: W3 | K4: W4 | L4: W5 | M4: W6 | N4: W7 | O4: W8 | P4: W9 | Q4: W10 | R4: W11 | S4: W12 | T4: W13 | U4: W14 | V4: W15 | W4: W16 | X4: W17 | Y4: W18 | Z4: W19 | AA4: W20 | AB4: W21 | AC4: W22
A5: 設計開發 | G5: 產品部
A6: 1.車輛採購 | B6: CADDY 自排 訂車 | G6: 管理部
A7: 2.到車 | B7: 到車 | G7: 管理部
A8: 3.內裝拆除 | B8: 內裝拆除 | G8: 產品部
A9: 4.切割車頂 | G9: 產品部
A10: 5.組裝上框 | G10: 產品部
A11: 6.防水件 | G11: 產品部
A12: 7.組裝上蓋 | G12: 產品部
A13: 8.側邊帳固定架組裝 | G13: 產品部
A14: 9.組裝側邊帳 | G14: 產品部
A15: 10防水與品質測試 | G15: 廠務部
AA16: 112/06/15 V01.TB-T53-1
A19: 三、法規認證 | G19: 設計組
A20: 掛案申請 （ARTC, VSCC） | G20: 產品部
A22: 測試治具製作 （供應商） | G22: 產品部
A24: 車殼測試 （輪椅位移、人偶、靜態安全帶鎖點） | G24: 產品部
A26: 實車測試 （670,040,020） | G26: 產品部
A28: 取得測試報告 （ARTC） | G28: 產品部
A30: 文件審查 （VSCC） | G30: 多功能小組
A32: 取得合格證 （交通部） | G32: 產品部
M33: ○
A34: 四、試產準備 | G34: 開發組
A35: 16. 產品、製程、品質系統確認 | G35: 多功能小組
S36: ▲
A37: 17. 製程及品檢工序確認 | G37: 多功能小組
S38: ▲
A39: 18. 生產設備、場地LAYOUT確認及佈置 | G39: 製造部
S40: ▲
A41: 19. 過程失效模式分析（PFEMA） | G41: 生技
A43: 20. 出貨物流、式樣確認 | G43: 管理部
R44: ○
A45: 21. 量測設備、工具確認 | G45: 品保部
A47: 22. 人員教育訓練 | G47: 生技＋技轉
S48: ▲
A49: 23. 階段審查 | G49: 多功能小組
S50: X
...

Sheet A表-附件-預算
B1: 露營車研發預算 及 (法規基礎款)量產件報價推估 | G1: 量產總計
E2: 研發總計 | F2: =SUM(E4:E20) -> 3180720
A3: 項目 | C3: 數量 | D3: 單位 | E3: 費用(含稅) | F3: 備註 | G3: 量產件報價(含稅)
A4: 材料費用 | B4: 原廠車輛 (2023年款-Caddy California露營車) | C4: 1 | D4: 輛 | E4: 1800000 | F4: 原廠告知會漲兩波的價格 若預計於明年度起案，原廠建議用 180 萬計算。 若於今年度起算，專案研發車輛用 169.8 萬 計算。
B5: 委製料件- 掀頂改高總成 (含 車頂內裝) - 國產化 | C5: 1 | D5: 式 | E5: 150000 | F5: 掀頂改高總成 (含 內裝) 及 委外工資
B6: 採購件- 側邊帳支架 | C6: 1 | D6: 組 | E6: 12000 | F6: 1組3個
B7: 合格汽車用滅火器 | C7: 1 | D7: 式 | E7: 1290 | F7: 太星電工車用滅火器
A8: 模治具費用 | B8: 掀頂 FRP 模具 | C8: 1 | D8: 式 | E8: 100000 | F8: 掀頂 FRP
A9: 製造費用 | B9: 車輛預計停留在工位/停車場佔位時間 | C9: =9*5*8 -> 360 | D9: 小時 | E9: =724*C9 -> 260640 | F9: 每小時724元，預計使用工位 9 週 | H9: 10天 | I9: 量產工位
A10: 人工費用 | B10: 人工費用 | C10: 4800 | D10: 人天 | E10: ='A表-大日程計畫表(橫展跨部版)'!L31*'A表-附件-預算'!C10 -> 669600 | F10: 人力工時，每小時600元，1人天4800元。被計算的人天工作詳表 1人月 = 22 人天、1人天=8人時 | H10: =2*10*4*600 -> 48000 | I10: 量產時間
A11: 測試 | B11: 拖車物流 | C11: 2 | D11: 趟 | E11: 7000 | F11: 福祉 - ARTC、ARTC-福祉 (若中華測試通過，可省一趟)
B12: 性能試驗測試 | C12: 1 | D12: 組 | E12: 100000 | F12: 原廠規定露營車機能、可靠、性能共8項測試
B13: 020. 車輛規格規定 | C13: 1 | D13: 案 | E13: 0 | F13: 020. 車輛規格規定
B14: 040. 靜態煞車 | C14: 1 | D14: 案 | E14: 0 | F14: M1類車輛(含編號020.3檢測)
B15: 770 客車車外突出限制 | C15: 1 | D15: 案 | E15: 44600
B16: 191 耐燃防焰材質測 | C16: 1 | D16: 案 | E16: 9400 | F16: 191 耐燃防焰材質測試 (須看委外供應商是否可以直接提供審查報告)
A17: 新車型審驗 | B17: 申請者資格登錄 | C17: 1 | D17: 案 | E17: 10030 | F17: 申請者資格變更登錄(新車型登錄)/品質一致性管制計畫書審查
B18: 車輛內裝材料變更登錄 | C18: 1 | D18: 案 | E18: 970 | F18: (申請者第一次申請「品質一致性管制計畫審查)
B19: 新車型式安全審驗 (併案監測 020. 車輛規格規定) - 原車頭 | C19: 1 | D19: 案 | E19: 10910 | F19: 小型車輛及小型汽車附掛之拖車尺度限制與重量之監測
B20: 新車型式安全審驗 (併案監測 020. 車輛規格規定) - 胖卡延伸 | C20: 1 | D20: 案 | E20: 4280 | F20: 延伸車型
F21: 112/06/15 V01.TB-T53-2

Sheet A表-附件-MSRP售價推估
B3: MSRP售價推估
C4: 台當數：1000台
F5: 方案一 | G5: 方案一
F6: 2023年度起案車價 169.8萬 | G6: 2024年度起案車價 180萬
B7: MSRP | F7: 超過原廠要望，需要進一步審計。 | G7: 超過原廠要望，需要進一步審計。
C8: 建議售價 (牌價) | F8: 228.9萬 | G8: 239.5萬
C9: 報價區間 | F9: 218萬-228萬 | G9: 229萬-239萬
C10: 業務底價 | F10: =F12+F11 -> 2179148.8 | G10: =G12+G11 -> 2281148.8
C11: 業代佣金(xxx萬以上)+業務交車獎金 | F11: 20000 | G11: 20000
C12: 無獎金價格 | F12: =SUM(F13:F16) -> 2159148.8 | G12: =SUM(G13:G16) -> 2261148.8
D13: 合理利潤 | E13: 0.1 | F13: =$F$34*E13 -> 0 | G13: =$F$34*F13 -> 0
D14: 推銷費用 | E14: 0.05 | F14: =$F$34*E14 -> 0 | G14: =$F$34*F14 -> 0
D15: 管理費用 | E15: 0.13 | F15: =$F$34*E15 -> 0 | G15: =$F$34*F15 -> 0
C16: 完成車價格(含稅) | F16: =SUM(F17:F25) -> 2159148.8 | G16: =SUM(G17:G25) -> 2261148.8
D17: 物流成本 | E17: 1趟5000 | F17: 5000 | G17: 5000
D18: 改裝稅 | E18: =E22*0.3 -> 0 | F18: =F22*30% -> 78987 | G18: =F22*30% -> 78987
D19: 改裝製造費用 | E19: 724 | F19: =E19*10*8 -> 57920 | G19: =E19*10*8 -> 57920
D20: 委製加工費用 | E20: 0 | F20: 0 | G20: 0
D21: 改裝人工成本 | E21: 600 | F21: =E21*10*8 -> 48000 | G21: =E21*10*8 -> 48000
D22: 改裝材料費 | F22: =SUM('A表-附件-預算'!E5:E8) -> 263290 | G22: =SUM('A表-附件-預算'!E5:E8) -> 263290
D23: 研發成本攤提(400台) | F23: ='A表-附件-預算'!F2/400 -> 7951.8 | G23: ='A表-附件-預算'!F2/400 -> 7951.8
D24: 經銷商折讓% | E24: 無折幅 | F24: 0 | G24: 0
D25: 原廠車價 | F25: 1698000 | G25: 1800000
G26: 112/06/15 V01.TB-T53-3
